Workbook

Sheet Акции
A1: Дата | B1: Бренд | C1: Артикул | D1: Скидка, % | E1: Сегмент | F1: 80 | G1: шт
A2: 45292 | B2: Astro Venture | C2: 63111 | D2: 0.2 | E2: =VLOOKUP(C2,Лист1!H:K,4,0) -> СТОК-ВИАТ | F2: =VLOOKUP(C2,Лист1!H:L,5,0) -> 416.1 | G2: =IFERROR(VLOOKUP(CONCATENATE(C2,A2),Лист1!D:E,2,0),0) -> 0
A3: 45292 | B3: Astro Venture | C3: 63112 | D3: 0.2 | E3: =VLOOKUP(C3,Лист1!H:K,4,0) -> СТОК-ВИАТ | F3: =VLOOKUP(C3,Лист1!H:L,5,0) -> 499.44 | G3: =IFERROR(VLOOKUP(CONCATENATE(C3,A3),Лист1!D:E,2,0),0) -> 0
A4: 45292 | B4: Astro Venture | C4: 63113 | D4: 0.2 | E4: =VLOOKUP(C4,Лист1!H:K,4,0) -> ВИАТ | F4: =VLOOKUP(C4,Лист1!H:L,5,0) -> 832.8 | G4: =IFERROR(VLOOKUP(CONCATENATE(C4,A4),Лист1!D:E,2,0),0) -> 0
A5: 45292 | B5: Astro Venture | C5: 63114 | D5: 0.2 | E5: =VLOOKUP(C5,Лист1!H:K,4,0) -> СТОК-ВИАТ | F5: =VLOOKUP(C5,Лист1!H:L,5,0) -> 1332.78 | G5: =IFERROR(VLOOKUP(CONCATENATE(C5,A5),Лист1!D:E,2,0),0) -> 0
A6: 45292 | B6: Astro Venture | C6: 63115 | D6: 0.2 | E6: =VLOOKUP(C6,Лист1!H:K,4,0) -> СТОК-ВИАТ | F6: =VLOOKUP(C6,Лист1!H:L,5,0) -> 1666.14 | G6: =IFERROR(VLOOKUP(CONCATENATE(C6,A6),Лист1!D:E,2,0),0) -> 0
A7: 45292 | B7: Astro Venture | C7: 63118 | D7: 0.2 | E7: =VLOOKUP(C7,Лист1!H:K,4,0) -> СТОК-ВИАТ | F7: =VLOOKUP(C7,Лист1!H:L,5,0) -> 1943.88 | G7: =IFERROR(VLOOKUP(CONCATENATE(C7,A7),Лист1!D:E,2,0),0) -> 0
A8: 45292 | B8: Astro Venture | C8: 63140 | D8: 0.2 | E8: =VLOOKUP(C8,Лист1!H:K,4,0) -> СТОК-ВИАТ | F8: =VLOOKUP(C8,Лист1!H:L,5,0) -> 1054.98 | G8: =IFERROR(VLOOKUP(CONCATENATE(C8,A8),Лист1!D:E,2,0),0) -> 0
A9: 45292 | B9: Astro Venture | C9: 63141 | D9: 0.2 | E9: =VLOOKUP(C9,Лист1!H:K,4,0) -> СТОК-ВИАТ | F9: =VLOOKUP(C9,Лист1!H:L,5,0) -> 721.68 | G9: =IFERROR(VLOOKUP(CONCATENATE(C9,A9),Лист1!D:E,2,0),0) -> 0
A10: 45292 | B10: Astro Venture | C10: 63142 | D10: 0.25 | E10: =VLOOKUP(C10,Лист1!H:K,4,0) -> СТОК-ВИАТ | F10: =VLOOKUP(C10,Лист1!H:L,5,0) -> 1832.76 | G10: =IFERROR(VLOOKUP(CONCATENATE(C10,A10),Лист1!D:E,2,0),0) -> 0
A11: 45292 | B11: Astro Venture | C11: 63146 | D11: 0.2 | E11: =VLOOKUP(C11,Лист1!H:K,4,0) -> СТОК-ВИАТ | F11: =VLOOKUP(C11,Лист1!H:L,5,0) -> 721.68 | G11: =IFERROR(VLOOKUP(CONCATENATE(C11,A11),Лист1!D:E,2,0),0) -> 0
A12: 45292 | B12: Astro Venture | C12: 63153 | D12: 0.2 | E12: =VLOOKUP(C12,Лист1!H:K,4,0) -> СТОК-ВИАТ | F12: =VLOOKUP(C12,Лист1!H:L,5,0) -> 832.8 | G12: =IFERROR(VLOOKUP(CONCATENATE(C12,A12),Лист1!D:E,2,0),0) -> 0
A13: 45292 | B13: Astro Venture | C13: 63154 | D13: 0.2 | E13: =VLOOKUP(C13,Лист1!H:K,4,0) -> СТОК-ВИАТ | F13: =VLOOKUP(C13,Лист1!H:L,5,0) -> 555 | G13: =IFERROR(VLOOKUP(CONCATENATE(C13,A13),Лист1!D:E,2,0),0) -> 0
... A53: 45292 | B53: Chap Mei | C53: 545314 | D53: 0.2 | E53: =VLOOKUP(C53,Лист1!H:K,4,0) -> ВИАТ | F53: =VLOOKUP(C53,Лист1!H:L,5,0) -> 666.12 | G53: =IFERROR(VLOOKUP(CONCATENATE(C53,A53),Лист1!D:E,2,0),0) -> 0
A54: 45292 | B54: Chap Mei | C54: 545008-1 | D54: 0.2 | E54: =VLOOKUP(C54,Лист1!H:K,4,0) -> СТОК-ВИАТ | F54: =VLOOKUP(C54,Лист1!H:L,5,0) -> 304.98 | G54: =IFERROR(VLOOKUP(CONCATENATE(C54,A54),Лист1!D:E,2,0),0) -> 0
A55: 45292 | B55: Chap Mei | C55: 545300-1 | D55: 0.2 | E55: =VLOOKUP(C55,Лист1!H:K,4,0) -> V | F55: =VLOOKUP(C55,Лист1!H:L,5,0) -> 277.2 | G55: =IFERROR(VLOOKUP(CONCATENATE(C55,A55),Лист1!D:E,2,0),0) -> 0
A56: 45292 | B56: Crystal Art | C56: CAFGR-MCU002 | D56: 0.2 | E56: =VLOOKUP(C56,Лист1!H:K,4,0) -> V | F56: =VLOOKUP(C56,Лист1!H:L,5,0) -> 110.58 | G56: =IFERROR(VLOOKUP(CONCATENATE(C56,A56),Лист1!D:E,2,0),0) -> 0
A57: 45292 | B57: Crystal Art | C57: CAFGR-MCU003 | D57: 0.2 | E57: =VLOOKUP(C57,Лист1!H:K,4,0) -> V | F57: =VLOOKUP(C57,Лист1!H:L,5,0) -> 110.58 | G57: =IFERROR(VLOOKUP(CONCATENATE(C57,A57),Лист1!D:E,2,0),0) -> 0
A58: 45292 | B58: Crystal Art | C58: CAFGR-MCU004 | D58: 0.2 | E58: =VLOOKUP(C58,Лист1!H:K,4,0) -> V | F58: =VLOOKUP(C58,Лист1!H:L,5,0) -> 110.58 | G58: =IFERROR(VLOOKUP(CONCATENATE(C58,A58),Лист1!D:E,2,0),0) -> 0
A59: 45292 | B59: Crystal Art | C59: CAFGR-MCU005 | D59: 0.2 | E59: =VLOOKUP(C59,Лист1!H:K,4,0) -> V | F59: =VLOOKUP(C59,Лист1!H:L,5,0) -> 110.58 | G59: =IFERROR(VLOOKUP(CONCATENATE(C59,A59),Лист1!D:E,2,0),0) -> 0
A60: 45292 | B60: Crystal Art | C60: CAFGR-MCU006 | D60: 0.2 | E60: =VLOOKUP(C60,Лист1!H:K,4,0) -> V | F60: =VLOOKUP(C60,Лист1!H:L,5,0) -> 110.58 | G60: =IFERROR(VLOOKUP(CONCATENATE(C60,A60),Лист1!D:E,2,0),0) -> 0
A61: 45292 | B61: Crystal Art | C61: CAFGR-MCU007 | D61: 0.2 | E61: =VLOOKUP(C61,Лист1!H:K,4,0) -> V | F61: =VLOOKUP(C61,Лист1!H:L,5,0) -> 110.58 | G61: =IFERROR(VLOOKUP(CONCATENATE(C61,A61),Лист1!D:E,2,0),0) -> 0
A62: 45292 | B62: Crystal Art | C62: CAFGR-SWS001 | D62: 0.2 | E62: =VLOOKUP(C62,Лист1!H:K,4,0) -> V | F62: =VLOOKUP(C62,Лист1!H:L,5,0) -> 110.58 | G62: =IFERROR(VLOOKUP(CONCATENATE(C62,A62),Лист1!D:E,2,0),0) -> 0
A63: 45292 | B63: Crystal Art | C63: CAFGR-SWS002 | D63: 0.2 | E63: =VLOOKUP(C63,Лист1!H:K,4,0) -> V | F63: =VLOOKUP(C63,Лист1!H:L,5,0) -> 110.58 | G63: =IFERROR(VLOOKUP(CONCATENATE(C63,A63),Лист1!D:E,2,0),0) -> 0
A64: 45292 | B64: Crystal Art | C64: CAFGR-SWS004 | D64: 0.2 | E64: =VLOOKUP(C64,Лист1!H:K,4,0) -> V | F64: =VLOOKUP(C64,Лист1!H:L,5,0) -> 110.58 | G64: =IFERROR(VLOOKUP(CONCATENATE(C64,A64),Лист1!D:E,2,0),0) -> 0
A65: 45292 | B65: Crystal Art | C65: CAFGR-SWS005 | D65: 0.2 | E65: =VLOOKUP(C65,Лист1!H:K,4,0) -> V | F65: =VLOOKUP(C65,Лист1!H:L,5,0) -> 110.58 | G65: =IFERROR(VLOOKUP(CONCATENATE(C65,A65),Лист1!D:E,2,0),0) -> 0
... A91: 45292 | B91: Cubic Fun | C91: T4039h | D91: 0.2 | E91: =VLOOKUP(C91,Лист1!H:K,4,0) -> В | F91: =VLOOKUP(C91,Лист1!H:L,5,0) -> 555 | G91: =IFERROR(VLOOKUP(CONCATENATE(C91,A91),Лист1!D:E,2,0),0) -> 0
A92: 45292 | B92: Dino Valley | C92: 542015 | D92: 0.2 | E92: =VLOOKUP(C92,Лист1!H:K,4,0) -> V | F92: =VLOOKUP(C92,Лист1!H:L,5,0) -> 360.54 | G92: =IFERROR(VLOOKUP(CONCATENATE(C92,A92),Лист1!D:E,2,0),0) -> 0
A93: 45292 | B93: Dino Valley | C93: 542017 | D93: 0.2 | E93: =VLOOKUP(C93,Лист1!H:K,4,0) -> V | F93: =VLOOKUP(C93,Лист1!H:L,5,0) -> 666.12 | G93: =IFERROR(VLOOKUP(CONCATENATE(C93,A93),Лист1!D:E,2,0),0) -> 0
A94: 45292 | B94: Dino Valley | C94: 542028 | D94: 0.2 | E94: =VLOOKUP(C94,Лист1!H:K,4,0) -> СТОК-ВИАТ | F94: =VLOOKUP(C94,Лист1!H:L,5,0) -> 332.76 | G94: =IFERROR(VLOOKUP(CONCATENATE(C94,A94),Лист1!D:E,2,0),0) -> 0
A95: 45292 | B95: Dino Valley | C95: 542051 | D95: 0.3 | E95: =VLOOKUP(C95,Лист1!H:K,4,0) -> СТОК-ВИАТ | F95: =VLOOKUP(C95,Лист1!H:L,5,0) -> 1110.54 | G95: =IFERROR(VLOOKUP(CONCATENATE(C95,A95),Лист1!D:E,2,0),0) -> 0
A96: 45292 | B96: Dino Valley | C96: 542076 | D96: 0.3 | E96: =VLOOKUP(C96,Лист1!H:K,4,0) -> СТОК-ВИАТ | F96: =VLOOKUP(C96,Лист1!H:L,5,0) -> 832.8 | G96: =IFERROR(VLOOKUP(CONCATENATE(C96,A96),Лист1!D:E,2,0),0) -> 0
A97: 45292 | B97: Dino Valley | C97: 542087 | D97: 0.2 | E97: =VLOOKUP(C97,Лист1!H:K,4,0) -> СТОК-ВИАТ | F97: =VLOOKUP(C97,Лист1!H:L,5,0) -> 499.44 | G97: =IFERROR(VLOOKUP(CONCATENATE(C97,A97),Лист1!D:E,2,0),0) -> 0
A98: 45292 | B98: Dino Valley | C98: 542090 | D98: 0.2 | E98: =VLOOKUP(C98,Лист1!H:K,4,0) -> СТОК-ВИАТ | F98: =VLOOKUP(C98,Лист1!H:L,5,0) -> 666.12 | G98: =IFERROR(VLOOKUP(CONCATENATE(C98,A98),Лист1!D:E,2,0),0) -> 0
A99: 45292 | B99: Dino Valley | C99: 542120 | D99: 0.2 | E99: =VLOOKUP(C99,Лист1!H:K,4,0) -> СТОК-ВИАТ | F99: =VLOOKUP(C99,Лист1!H:L,5,0) -> 666.12 | G99: =IFERROR(VLOOKUP(CONCATENATE(C99,A99),Лист1!D:E,2,0),0) -> 0
A100: 45292 | B100: Dino Valley | C100: 542015-1 | D100: 0.2 | E100: =VLOOKUP(C100,Лист1!H:K,4,0) -> V | F100: =VLOOKUP(C100,Лист1!H:L,5,0) -> 360.54 | G100: =IFERROR(VLOOKUP(CONCATENATE(C100,A100),Лист1!D:E,2,0),0) -> 0
A101: 45292 | B101: Dino Valley | C101: 542083-2 | D101: 0.2 | E101: =VLOOKUP(C101,Лист1!H:K,4,0) -> СТОК-ВИАТ | F101: =VLOOKUP(C101,Лист1!H:L,5,0) -> 388.32 | G101: =IFERROR(VLOOKUP(CONCATENATE(C101,A101),Лист1!D:E,2,0),0) -> 0
A102: 45292 | B102: Djeco | C102: DD03485 | D102: 0.2 | E102: =VLOOKUP(C102,Лист1!H:K,4,0) -> СТОК-ВИАТ | F102: =VLOOKUP(C102,Лист1!H:L,5,0) -> 304.98 | G102: =IFERROR(VLOOKUP(CONCATENATE(C102,A102),Лист1!D:E,2,0),0) -> 0
A103: 45292 | B103: Djeco | C103: DD04670 | D103: 0.2 | E103: =VLOOKUP(C103,Лист1!H:K,4,0) -> V | F103: =VLOOKUP(C103,Лист1!H:L,5,0) -> 555 | G103: =IFERROR(VLOOKUP(CONCATENATE(C103,A103),Лист1!D:E,2,0),0) -> 0
A104: 45292 | B104: Djeco | C104: DD04671 | D104: 0.2 | E104: =VLOOKUP(C104,Лист1!H:K,4,0) -> V | F104: =VLOOKUP(C104,Лист1!H:L,5,0) -> 555 | G104: =IFERROR(VLOOKUP(CONCATENATE(C104,A104),Лист1!D:E,2,0),0) -> 0
...

Sheet Лист1
A1: Номенклатура.Артикул | B1: Період, Місяць.Початок місяця | C1: Выручка | E1: Выручка
A2: 004627I | B2: 01.01.2025 | C2: 30 | D2: =CONCATENATE(A2,B2*1) -> 004627I45658 | E2: 30 | H2: 3361 | I2: 50 IQ завдань Динозаври | J2: шт | K2: СТОК-ВИАТ | L2: 166.14
A3: 004627I | B3: 01.02.2025 | C3: 27 | D3: =CONCATENATE(A3,B3*1) -> 004627I45689 | E3: 27 | H3: 378 | I3: 50 IQ завдань Єдинороги | J3: шт | K3: СТОК-ВИАТ | L3: 166.14
A4: 004627I | B4: 01.03.2025 | C4: 20 | D4: =CONCATENATE(A4,B4*1) -> 004627I45717 | E4: 20 | H4: 572609 | I4: Anne Geddes Лялька "Маленька Зебра", 31 см | J4: шт | K4: V | L4: 499.44
A5: 004627I | B5: 01.04.2025 | C5: 27 | D5: =CONCATENATE(A5,B5*1) -> 004627I45748 | E5: 27 | H5: 572611 | I5: Anne Geddes Лялька "Маленька Коала", 31 см | J5: шт | K5: V | L5: 499.44
A6: 004627I | B6: 01.05.2025 | C6: 15 | D6: =CONCATENATE(A6,B6*1) -> 004627I45778 | E6: 15 | H6: 21071AG | I6: Anne Geddes Лялька "Маленьке Ведмежатко" з сумкою та стікерами, 23 см | J6: шт | K6: V | L6: 388.32
A7: 004627I | B7: 01.06.2025 | C7: 27 | D7: =CONCATENATE(A7,B7*1) -> 004627I45809 | E7: 27 | H7: 572618 | I7: Anne Geddes Лялька "Маленьке Ведмежатко", 31 см | J7: шт | K7: V | L7: 555
A8: 004627I | B8: 01.07.2025 | C8: 17 | D8: =CONCATENATE(A8,B8*1) -> 004627I45839 | E8: 17 | H8: 21072 | I8: Anne Geddes Лялька "Маленьке Зайченя" з сумкою та стікерами, 23 см | J8: шт | K8: V | L8: 388.32
A9: 004627I | B9: 01.08.2025 | C9: 27 | D9: =CONCATENATE(A9,B9*1) -> 004627I45870 | E9: 27 | H9: 572620 | I9: Anne Geddes Лялька "Маленьке Зайченя", 31 см | J9: шт | K9: V | L9: 555
A10: 004627I | B10: 01.09.2025 | C10: 19 | D10: =CONCATENATE(A10,B10*1) -> 004627I45901 | E10: 19 | H10: 572610 | I10: Anne Geddes Лялька "Маленький Жирафик", 31 см | J10: шт | K10: V | L10: 499.44
A11: 004627I | B11: 01.10.2025 | C11: 21 | D11: =CONCATENATE(A11,B11*1) -> 004627I45931 | E11: 21 | H11: 575706 | I11: Anne Geddes Набір ляльок "Маленькі сестри Кошенятка", 38 см та 23см | J11: шт | K11: V | L11: 777.24
A12: 004627I | B12: 01.11.2025 | C12: 25 | D12: =CONCATENATE(A12,B12*1) -> 004627I45962 | E12: 25 | H12: 4003 | I12: Aqua Dragons - Набір DELUXUE | J12: шт | K12: СТОК-ВИАТ | L12: 77.22
A13: 004627I | B13: 01.12.2025 | C13: 64 | D13: =CONCATENATE(A13,B13*1) -> 004627I45992 | E13: 64 | H13: 4004 | I13: Aqua Dragons - Нове Життя | J13: шт | K13: СТОК-ВИАТ | L13: 32.76
A14: 004885I | B14: 01.03.2025 | C14: 1 | D14: =CONCATENATE(A14,B14*1) -> 004885I45717 | E14: 1 | H14: 4001 | I14: Aqua Dragons - Підводний світ | J14: шт | K14: СТОК-ВИАТ | L14: 60.54
A15: 004885I | B15: 01.07.2025 | C15: 2 | D15: =CONCATENATE(A15,B15*1) -> 004885I45839 | E15: 2 | H15: PAW22301 | I15: AquaSound Килимок для малювання на водній основі "Magiс aqua sounds PAW Patrol" | J15: шт | K15: ВИАТ | L15: 777.24
A16: 004885I | B16: 01.08.2025 | C16: 32 | D16: =CONCATENATE(A16,B16*1) -> 004885I45870 | E16: 32 | H16: 77021 | I16: Baby Secrets Ігровий набір з колискою | J16: шт | K16: СТОК-ВИАТ | L16: 110.58
A17: 004885I | B17: 01.09.2025 | C17: 39 | D17: =CONCATENATE(A17,B17*1) -> 004885I45901 | E17: 39 | H17: 77020 | I17: Baby Secrets Ігровий набір з коляскою | J17: шт | K17: СТОК-ВИАТ | L17: 55.02
A18: 004885I | B18: 01.10.2025 | C18: 61 | D18: =CONCATENATE(A18,B18*1) -> 004885I45931 | E18: 61 | H18: 77022 | I18: Baby Secrets Ігровий набір з коником-качалкою | J18: шт | K18: СТОК-ВИАТ | L18: 55.02
A19: 004885I | B19: 01.11.2025 | C19: 51 | D19: =CONCATENATE(A19,B19*1) -> 004885I45962 | E19: 51 | H19: 76922 | I19: Baby Secrets Ігровий набір з пупсиком (50 видів у асортименті) | J19: шт | K19: СТОК-ВИАТ | L19: 32.76
A20: 004885I | B20: 01.12.2025 | C20: 23 | D20: =CONCATENATE(A20,B20*1) -> 004885I45992 | E20: 23 | H20: 77023 | I20: Baby Secrets Ігровий набір зі стільчиком для годування | J20: шт | K20: СТОК-ВИАТ | L20: 110.58
A21: 004896I | B21: 01.01.2025 | C21: 64 | D21: =CONCATENATE(A21,B21*1) -> 004896I45658 | E21: 64 | H21: BHR17 | I21: Bad Habbit Rabbitz іграшка плюшева колекційна | J21: шт | K21: Новинка | L21: 277.2
A22: 004896I | B22: 01.02.2025 | C22: 37 | D22: =CONCATENATE(A22,B22*1) -> 004896I45689 | E22: 37 | H22: 113506 | I22: Baobab Набір 3в1 : Дитячим сповивальний столик з аксесуарами | J22: шт | K22: СТОК-ВИАТ | L22: 193.86
A23: 004896I | B23: 01.03.2025 | C23: 43 | D23: =CONCATENATE(A23,B23*1) -> 004896I45717 | E23: 43 | H23: 113504 | I23: Baobab Набір 4в1 : Пупсик Камілла BEBE VANILLE з дитячим сповивальним столиком і аксесуарами | J23: шт | K23: СТОК-ВИАТ | L23: 55.02
A24: 004896I | B24: 01.04.2025 | C24: 43 | D24: =CONCATENATE(A24,B24*1) -> 004896I45748 | E24: 43 | H24: 113503 | I24: Baobab Пупсик зі звуковими ефектами Камілла BEBE VANILLE | J24: шт | K24: СТОК-ВИАТ | L24: 143.88
A25: 004896I | B25: 01.05.2025 | C25: 44 | D25: =CONCATENATE(A25,B25*1) -> 004896I45778 | E25: 44 | H25: 113508 | I25: Baobab Пупсик інтерактивний Емма BEBE VANILLE | J25: шт | K25: СТОК-ВИАТ | L25: 55.02
A26: 004896I | B26: 01.06.2025 | C26: 35 | D26: =CONCATENATE(A26,B26*1) -> 004896I45809 | E26: 35 | H26: 113511 | I26: Baobab Пупсик інтерактивний Клара BEBE VANILLE з аксесуарами | J26: шт | K26: СТОК-ВИАТ | L26: 243.9
A27: 004896I | B27: 01.07.2025 | C27: 52 | D27: =CONCATENATE(A27,B27*1) -> 004896I45839 | E27: 52 | H27: 113500 | I27: Baobab Пупсик інтерактивний Марго BEBE VANILLE | J27: шт | K27: СТОК-ВИАТ | L27: 55.02
A28: 004896I | B28: 01.08.2025 | C28: 40 | D28: =CONCATENATE(A28,B28*1) -> 004896I45870 | E28: 40 | H28: 113502 | I28: Baobab Пупсик інтерактивний Хлоя BEBE VANILLE | J28: шт | K28: СТОК-ВИАТ | L28: 55.02
A29: 004896I | B29: 01.09.2025 | C29: 39 | D29: =CONCATENATE(A29,B29*1) -> 004896I45901 | E29: 39 | H29: 113505 | I29: Baobab Пупсик Камілла BEBE VANILLE з коляскою | J29: шт | K29: СТОК-ВИАТ | L29: 243.9
A30: 004896I | B30: 01.10.2025 | C30: 42 | D30: =CONCATENATE(A30,B30*1) -> 004896I45931 | E30: 42 | H30: 113507 | I30: Baobab Пупсик Камілла BEBE VANILLE зі стільчиком для годування | J30: шт | K30: СТОК-ВИАТ | L30: 55.02
A31: 004896I | B31: 01.11.2025 | C31: 40 | D31: =CONCATENATE(A31,B31*1) -> 004896I45962 | E31: 40 | H31: 961017 | I31: Besties 3D наліпки з блискітками "Зірка" (12 шт) | J31: шт | K31: С | L31: 38.34
A32: 004896I | B32: 01.12.2025 | C32: 28 | D32: =CONCATENATE(A32,B32*1) -> 004896I45992 | E32: 28 | H32: 961016 | I32: Besties 3D наліпки з блискітками "Серце" (12 шт) | J32: шт | K32: С | L32: 38.34
A33: 004909I | B33: 01.01.2025 | C33: 47 | D33: =CONCATENATE(A33,B33*1) -> 004909I45658 | E33: 47 | H33: 961040 | I33: Besties Арт-мозаїка "Зимова красуня"/ Бестіс Арт-мозаїка "Зимова красуня" | J33: шт | K33: С | L33: 55.02
... A71: 005053I | B71: 01.05.2025 | C71: 1 | D71: =CONCATENATE(A71,B71*1) -> 005053I45778 | E71: 1 | H71: 961037 | I71: Besties Стікербук за номерами «Summer»/ Бестіс Стікербук за номерами «Самер» | J71: шт | K71: С | L71: 66.12
A72: 5058 | B72: 01.01.2025 | C72: 15 | D72: =CONCATENATE(A72,B72*1) -> 505845658 | E72: 15 | H72: 961022 | I72: Besties Щоденник А5 з чарівною ручкою (50 аркушів, фіолетовий) | J72: шт | K72: В | L72: 154.98
A73: 5058 | B73: 01.02.2025 | C73: 22 | D73: =CONCATENATE(A73,B73*1) -> 505845689 | E73: 22 | H73: 961007 | I73: Besties Щоденник А5 з чарівною ручкою (50 аркушів) | J73: шт | K73: V | L73: 154.98
A74: 5058 | B74: 01.03.2025 | C74: 13 | D74: =CONCATENATE(A74,B74*1) -> 505845717 | E74: 13 | H74: 961021 | I74: Besties Щоденник А5 із замочком (60 аркушів) | J74: шт | K74: В | L74: 138.36
A75: 5058 | B75: 01.04.2025 | C75: 8 | D75: =CONCATENATE(A75,B75*1) -> 505845748 | E75: 8 | H75: 961044 | I75: Besties Щоденник із замочком "Зимовий секрет"/ Бестіс Щоденник із замочком "Зимовий секрет" | J75: шт | K75: С | L75: 138.36
A76: 5058 | B76: 01.05.2025 | C76: 6 | D76: =CONCATENATE(A76,B76*1) -> 505845778 | E76: 6 | H76: BL7014UK(UA) | I76: Blasta Набір BLASTA BOYS 6 фл. + 4 трафарети | J76: шт | K76: СТОК-ВИАТ | L76: 55.02
A77: 5058 | B77: 01.06.2025 | C77: 7 | D77: =CONCATENATE(A77,B77*1) -> 505845809 | E77: 7 | H77: BL7016UK(UA) | I77: Blasta Набір BLASTA GARAGE 12 фл. + 3 авто + гараж | J77: шт | K77: СТОК-ВИАТ | L77: 49.44
...
